Workbook
Name нгн: #REF!
Name нгн: #REF!
Name нгн: #REF!
Name нгн: #REF!
Name нгн: #REF!
Name нгн: #REF!
Name нгн: #REF!
Name нгн: #REF!
Name нгн: #REF!
Name нгн: #REF!
Name нгн: #REF!
Name нгн: #REF!
Name ннннннн: #REF!
Name ннннннн: #REF!
Name ннннннн: #REF!
Name ннннннн: #REF!
Name ннннннн: #REF!
Name ннннннн: #REF!
Name ннннннн: #REF!
Name ннннннн: #REF!
Name ннннннн: #REF!
Name ннннннн: #REF!
Name ннннннн: #REF!
Name ннннннн: #REF!
Name ннннннн: #REF!
Name ннннннн: #REF!
Name ннннннн: #REF!
Name оло: #REF!
Name оло: #REF!
Name оло: #REF!
Name оло: #REF!
Name оло: #REF!
Name оло: #REF!
Name оло: #REF!
Name оло: #REF!
Name оло: #REF!
Name оло: #REF!
Name оло: #REF!
Name оло: #REF!
Name оло: #REF!
Name оло: #REF!
Name оло: #REF!
Name Условие: #REF!
Name Условие: #REF!
Name Условие: #REF!
Name Условие: #REF!
Name Условие: #REF!
Name Условие: #REF!
Name Условие: #REF!
Name Условие: #REF!
Name Условие: #REF!
Name Условие: #REF!
Name Условие: #REF!
Name Условие: #REF!
Name Условие: #REF!
Name Условие: #REF!
Name Условие: #REF!
Name Условие: #REF!

Sheet Справочники
A1: Отдел | B1: Должность | C1: Оклад | F1: Отдел | G1: Телефон | H1: Рабочий телефон
A2: Бухгалтерия | B2: Бухгалтер | C2: 12000 | F2: Бухгалтерия | G2: 643201 | H2: =CONCATENATE("+7(8332)", MID(G2, 1, 2), "-", MID(G2, 3, 2), "-", MID(G2, 5, 2)) -> +7(8332)64-32-01
A3: Технологический отдел | B3: Ведущий специалист | C3: 17000 | F3: Технологический отдел | G3: 643214 | H3: =CONCATENATE("+7(8332)", MID(G3, 1, 2), "-", MID(G3, 3, 2), "-", MID(G3, 5, 2)) -> +7(8332)64-32-14
A4: Технологический отдел | B4: Верстальщик | C4: 12000 | F4: Транспортный отдел | G4: 643231 | H4: =CONCATENATE("+7(8332)", MID(G4, 1, 2), "-", MID(G4, 3, 2), "-", MID(G4, 5, 2)) -> +7(8332)64-32-31
A5: Транспортный отдел | B5: Водитель | C5: 12000 | F5: Редакторский отдел | G5: 643213 | H5: =CONCATENATE("+7(8332)", MID(G5, 1, 2), "-", MID(G5, 3, 2), "-", MID(G5, 5, 2)) -> +7(8332)64-32-13
A6: Бухгалтерия | B6: Главный бухгалтер | C6: 20000 | F6: Склад | G6: 643223 | H6: =CONCATENATE("+7(8332)", MID(G6, 1, 2), "-", MID(G6, 3, 2), "-", MID(G6, 5, 2)) -> +7(8332)64-32-23
A7: Редакторский отдел | B7: Главный редактор | C7: 20000 | F7: Управление | G7: 643210 | H7: =CONCATENATE("+7(8332)", MID(G7, 1, 2), "-", MID(G7, 3, 2), "-", MID(G7, 5, 2)) -> +7(8332)64-32-10
A8: Технологический отдел | B8: Главный технолог | C8: 22000 | F8: Отдел худ. оформления | G8: 643220 | H8: =CONCATENATE("+7(8332)", MID(G8, 1, 2), "-", MID(G8, 3, 2), "-", MID(G8, 5, 2)) -> +7(8332)64-32-20
A9: Склад | B9: Грузчик | C9: 11000 | F9: Рекламный отдел | G9: 643217 | H9: =CONCATENATE("+7(8332)", MID(G9, 1, 2), "-", MID(G9, 3, 2), "-", MID(G9, 5, 2)) -> +7(8332)64-32-17
A10: Управление | B10: Директор | C10: 35000 | F10: Отдел продаж | G10: 643218 | H10: =CONCATENATE("+7(8332)", MID(G10, 1, 2), "-", MID(G10, 3, 2), "-", MID(G10, 5, 2)) -> +7(8332)64-32-18
A11: Транспортный отдел | B11: Диспетчер | C11: 12000
A12: Бухгалтерия | B12: Зам. гл. бухгалтера | C12: 17000
A13: Редакторский отдел | B13: Зам. гл. редактора | C13: 19000
A14: Управление | B14: Зам. директора | C14: 28000
A15: Отдел худ. оформления | B15: Зам. начальника отдела | C15: 18000
A16: Бухгалтерия | B16: Кассир | C16: 12000
A17: Склад | B17: Кладовщик | C17: 15000
A18: Редакторский отдел | B18: Корректор | C18: 14000
A19: Технологический отдел | B19: Машинистка | C19: 12000
A20: Рекламный отдел | B20: Менеджер | C20: 15000
A21: Отдел продаж | B21: Менеджер | C21: 15000
A22: Рекламный отдел | B22: Начальник отдела | C22: 22000
... A35: Бухгалтерия | B35: Экономист | C35: 15000

Sheet База данных
A1: Табельный номер | B1: Фамилия | C1: Имя | D1: Отчество | E1: Пол | F1: Отдел | G1: Должность | H1: Оклад | I1: Образование | J1: Дата найма | K1: Дата рождения | L1: Стаж | M1: Возраст | N1: Рабочий телефон
A2: 101 | B2: Айдарпашич | C2: Амина | D2: Александровна | E2: жен | F2: =LOOKUP(G2,Справочники!$B$2:$B$35,Справочники!$A$2:$A$35) -> Бухгалтерия | G2: Бухгалтер | H2: =LOOKUP(G2,Справочники!$B$2:$B$35,Справочники!$C$2:$C$35) -> 12000 | I2: высшее | J2: 38944 | K2: 30198 | L2: =DATEDIF(J2, TODAY(),"Y") -> 16 | M2: =DATEDIF(K2, TODAY(),"Y") -> 40 | N2: =LOOKUP(F2,Справочники!$F$2:$F$10,Справочники!$H$2:$H$10) -> +7(8332)64-32-01
A3: 102 | B3: Вербицкая | C3: Елена | D3: Вадимовна | E3: жен | F3: =LOOKUP(G3,Справочники!$B$2:$B$35,Справочники!$A$2:$A$35) -> Бухгалтерия | G3: Главный бухгалтер | H3: =LOOKUP(G3,Справочники!$B$2:$B$35,Справочники!$C$2:$C$35) -> 20000 | I3: высшее | J3: 34380 | K3: 25186 | L3: =DATEDIF(J3, TODAY(),"Y") -> 28 | M3: =DATEDIF(K3, TODAY(),"Y") -> 53 | N3: =LOOKUP(F3,Справочники!$F$2:$F$10,Справочники!$H$2:$H$10) -> +7(8332)64-32-01
A4: 103 | B4: Иванова | C4: Людмила | D4: Петровна | E4: жен | F4: =LOOKUP(G4,Справочники!$B$2:$B$35,Справочники!$A$2:$A$35) -> Бухгалтерия | G4: Кассир | H4: =LOOKUP(G4,Справочники!$B$2:$B$35,Справочники!$C$2:$C$35) -> 12000 | I4: среднее специальное | J4: 42962 | K4: 34762 | L4: =DATEDIF(J4, TODAY(),"Y") -> 5 | M4: =DATEDIF(K4, TODAY(),"Y") -> 27 | N4: =LOOKUP(F4,Справочники!$F$2:$F$10,Справочники!$H$2:$H$10) -> +7(8332)64-32-01
A5: 104 | B5: Лобурец | C5: Диана | D5: Борисовна | E5: жен | F5: =LOOKUP(G5,Справочники!$B$2:$B$35,Справочники!$A$2:$A$35) -> Бухгалтерия | G5: Экономист | H5: =LOOKUP(G5,Справочники!$B$2:$B$35,Справочники!$C$2:$C$35) -> 15000 | I5: высшее | J5: 41530 | K5: 25346 | L5: =DATEDIF(J5, TODAY(),"Y") -> 9 | M5: =DATEDIF(K5, TODAY(),"Y") -> 53 | N5: =LOOKUP(F5,Справочники!$F$2:$F$10,Справочники!$H$2:$H$10) -> +7(8332)64-32-01
A6: 105 | B6: Алеев | C6: Леонид | D6: Иванович | E6: муж | F6: =LOOKUP(G6,Справочники!$B$2:$B$35,Справочники!$A$2:$A$35) -> Бухгалтерия | G6: Зам. гл. бухгалтера | H6: =LOOKUP(G6,Справочники!$B$2:$B$35,Справочники!$C$2:$C$35) -> 17000 | I6: высшее | J6: 41165 | K6: 31196 | L6: =DATEDIF(J6, TODAY(),"Y") -> 10 | M6: =DATEDIF(K6, TODAY(),"Y") -> 37 | N6: =LOOKUP(F6,Справочники!$F$2:$F$10,Справочники!$H$2:$H$10) -> +7(8332)64-32-01
A7: 106 | B7: Левитин | C7: Евгений | D7: Валерьянович | E7: муж | F7: =LOOKUP(G7,Справочники!$B$2:$B$35,Справочники!$A$2:$A$35) -> Бухгалтерия | G7: Бухгалтер | H7: =LOOKUP(G7,Справочники!$B$2:$B$35,Справочники!$C$2:$C$35) -> 12000 | I7: неполное высшее | J7: 42626 | K7: 31062 | L7: =DATEDIF(J7, TODAY(),"Y") -> 6 | M7: =DATEDIF(K7, TODAY(),"Y") -> 37 | N7: =LOOKUP(F7,Справочники!$F$2:$F$10,Справочники!$H$2:$H$10) -> +7(8332)64-32-01
A8: 107 | B8: Богуславская | C8: Дарья | D8: Вячеславовна | E8: жен | F8: =LOOKUP(G8,Справочники!$B$2:$B$35,Справочники!$A$2:$A$35) -> Управление | G8: Референт | H8: =LOOKUP(G8,Справочники!$B$2:$B$35,Справочники!$C$2:$C$35) -> 15000 | I8: среднее специальное | J8: 39956 | K8: 30254 | L8: =DATEDIF(J8, TODAY(),"Y") -> 13 | M8: =DATEDIF(K8, TODAY(),"Y") -> 40 | N8: =LOOKUP(F8,Справочники!$F$2:$F$10,Справочники!$H$2:$H$10) -> +7(8332)64-32-18
A9: 108 | B9: Иванов | C9: Александр | D9: Геннадиевич | E9: муж | F9: =LOOKUP(G9,Справочники!$B$2:$B$35,Справочники!$A$2:$A$35) -> Управление | G9: Директор | H9: =LOOKUP(G9,Справочники!$B$2:$B$35,Справочники!$C$2:$C$35) -> 35000 | I9: высшее | J9: 38579 | K9: 28499 | L9: =DATEDIF(J9, TODAY(),"Y") -> 17 | M9: =DATEDIF(K9, TODAY(),"Y") -> 44 | N9: =LOOKUP(F9,Справочники!$F$2:$F$10,Справочники!$H$2:$H$10) -> +7(8332)64-32-18
A10: 109 | B10: Васильев | C10: Леонид | D10: Сергеевич | E10: муж | F10: =LOOKUP(G10,Справочники!$B$2:$B$35,Справочники!$A$2:$A$35) -> Управление | G10: Зам. директора | H10: =LOOKUP(G10,Справочники!$B$2:$B$35,Справочники!$C$2:$C$35) -> 28000 | I10: высшее | J10: 39103 | K10: 27786 | L10: =DATEDIF(J10, TODAY(),"Y") -> 15 | M10: =DATEDIF(K10, TODAY(),"Y") -> 46 | N10: =LOOKUP(F10,Справочники!$F$2:$F$10,Справочники!$H$2:$H$10) -> +7(8332)64-32-18
A11: 110 | B11: Федотова | C11: Инна | D11: Николаевна | E11: жен | F11: =LOOKUP(G11,Справочники!$B$2:$B$35,Справочники!$A$2:$A$35) -> Управление | G11: Финансовый директор | H11: =LOOKUP(G11,Справочники!$B$2:$B$35,Справочники!$C$2:$C$35) -> 30000 | I11: высшее | J11: 34436 | K11: 26821 | L11: =DATEDIF(J11, TODAY(),"Y") -> 28 | M11: =DATEDIF(K11, TODAY(),"Y") -> 49 | N11: =LOOKUP(F11,Справочники!$F$2:$F$10,Справочники!$H$2:$H$10) -> +7(8332)64-32-18
A12: 111 | B12: Прохорова | C12: Татьяна | D12: Петровна | E12: жен | F12: =LOOKUP(G12,Справочники!$B$2:$B$35,Справочники!$A$2:$A$35) -> Управление | G12: Секретарь | H12: =LOOKUP(G12,Справочники!$B$2:$B$35,Справочники!$C$2:$C$35) -> 15000 | I12: неполное высшее | J12: 42960 | K12: 33207 | L12: =DATEDIF(J12, TODAY(),"Y") -> 5 | M12: =DATEDIF(K12, TODAY(),"Y") -> 31 | N12: =LOOKUP(F12,Справочники!$F$2:$F$10,Справочники!$H$2:$H$10) -> +7(8332)64-32-18
A13: 112 | B13: Максимов | C13: Андрей | D13: Леонидович | E13: муж | F13: =LOOKUP(G13,Справочники!$B$2:$B$35,Справочники!$A$2:$A$35) -> Рекламный отдел | G13: Начальник отдела | H13: =LOOKUP(G13,Справочники!$B$2:$B$35,Справочники!$C$2:$C$35) -> 22000 | I13: высшее | J13: 40966 | K13: 31390 | L13: =DATEDIF(J13, TODAY(),"Y") -> 10 | M13: =DATEDIF(K13, TODAY(),"Y") -> 36 | N13: =LOOKUP(F13,Справочники!$F$2:$F$10,Справочники!$H$2:$H$10) -> +7(8332)64-32-01
... A65: 164 | B65: Толоконникова | C65: Майя | D65: Кириловна | E65: жен | F65: =LOOKUP(G65,Справочники!$B$2:$B$35,Справочники!$A$2:$A$35) -> Транспортный отдел | G65: Диспетчер | H65: =LOOKUP(G65,Справочники!$B$2:$B$35,Справочники!$C$2:$C$35) -> 12000 | I65: среднее | J65: 43438 | K65: 34714 | L65: =DATEDIF(J65, TODAY(),"Y") -> 3 | M65: =DATEDIF(K65, TODAY(),"Y") -> 27 | N65: =LOOKUP(F65,Справочники!$F$2:$F$10,Справочники!$H$2:$H$10) -> +7(8332)64-32-18

Sheet Октябрь
A1: Ведомость начисления заработной платы | I1: за октябрь 2019 | S1: Рабочий телефон
F2: 0.1 | G2: 0.15 | I2: 0.13 | S2: Рабочий телефон
A3: Табельный номер | B3: Фамилия | C3: Имя | D3: Отчество | E3: Оклад | F3: Премия | G3: Районный коэффициент | H3: Начислено | I3: НДФЛ | J3: К выдаче | K3: Пол | L3: Отдел | M3: Должность | N3: Образование | O3: Дата найма | P3: Стаж | Q3: Дата рождения | R3: Возраст | S3: Рабочий телефон
A4: 101 | B4: Айдарпашич | C4: Амина | D4: Александровна | E4: =LOOKUP(M4,Справочники!$B$2:$B$35,Справочники!$C$2:$C$35) -> 12000 | F4: =IF(P4>=5, E4*$F$2, ) -> 1200 | G4: =E4*$G$2 -> 1800 | H4: =E4+F4+G4 -> 15000 | I4: =H4*$I$2 -> 1950 | J4: =H4-I4 -> 13050 | K4: жен | L4: =LOOKUP(M4,Справочники!$B$2:$B$35,Справочники!$A$2:$A$35) -> Бухгалтерия | M4: Бухгалтер | N4: высшее | O4: 38944 | P4: =DATEDIF(O4, TODAY(),"Y") -> 16 | Q4: 30198 | R4: =DATEDIF(Q4, TODAY(),"Y") -> 40 | S4: =LOOKUP(L4,Справочники!$F$2:$F$10,Справочники!$H$2:$H$10) -> +7(8332)64-32-01
A5: 105 | B5: Алеев | C5: Леонид | D5: Иванович | E5: =LOOKUP(M5,Справочники!$B$2:$B$35,Справочники!$C$2:$C$35) -> 17000 | F5: =IF(P5>=5, E5*$F$2, ) -> 1700 | G5: =E5*$G$2 -> 2550 | H5: =E5+F5+G5 -> 21250 | I5: =H5*$I$2 -> 2762.5 | J5: =H5-I5 -> 18487.5 | K5: муж | L5: =LOOKUP(M5,Справочники!$B$2:$B$35,Справочники!$A$2:$A$35) -> Бухгалтерия | M5: Зам. гл. бухгалтера | N5: высшее | O5: 41165 | P5: =DATEDIF(O5, TODAY(),"Y") -> 10 | Q5: 31196 | R5: =DATEDIF(Q5, TODAY(),"Y") -> 37 | S5: =LOOKUP(L5,Справочники!$F$2:$F$10,Справочники!$H$2:$H$10) -> +7(8332)64-32-01
A6: 130 | B6: Арбузова | C6: Маргарита | D6: Ивановна | E6: =LOOKUP(M6,Справочники!$B$2:$B$35,Справочники!$C$2:$C$35) -> 15000 | F6: =IF(P6>=5, E6*$F$2, ) -> 1500 | G6: =E6*$G$2 -> 2250 | H6: =E6+F6+G6 -> 18750 | I6: =H6*$I$2 -> 2437.5 | J6: =H6-I6 -> 16312.5 | K6: жен | L6: =LOOKUP(M6,Справочники!$B$2:$B$35,Справочники!$A$2:$A$35) -> Управление | M6: Референт | N6: неполное высшее | O6: 42765 | P6: =DATEDIF(O6, TODAY(),"Y") -> 5 | Q6: 34714 | R6: =DATEDIF(Q6, TODAY(),"Y") -> 27 | S6: =LOOKUP(L6,Справочники!$F$2:$F$10,Справочники!$H$2:$H$10) -> +7(8332)64-32-18
A7: 139 | B7: Белозерова | C7: Ольга | D7: Владимировна | E7: =LOOKUP(M7,Справочники!$B$2:$B$35,Справочники!$C$2:$C$35) -> 15000 | F7: =IF(P7>=5, E7*$F$2, ) -> 1500 | G7: =E7*$G$2 -> 2250 | H7: =E7+F7+G7 -> 18750 | I7: =H7*$I$2 -> 2437.5 | J7: =H7-I7 -> 16312.5 | K7: жен | L7: =LOOKUP(M7,Справочники!$B$2:$B$35,Справочники!$A$2:$A$35) -> Управление | M7: Референт | N7: среднее специальное | O7: 41697 | P7: =DATEDIF(O7, TODAY(),"Y") -> 8 | Q7: 33022 | R7: =DATEDIF(Q7, TODAY(),"Y") -> 32 | S7: =LOOKUP(L7,Справочники!$F$2:$F$10,Справочники!$H$2:$H$10) -> +7(8332)64-32-18
A8: 107 | B8: Богуславская | C8: Дарья | D8: Вячеславовна | E8: =LOOKUP(M8,Справочники!$B$2:$B$35,Справочники!$C$2:$C$35) -> 15000 | F8: =IF(P8>=5, E8*$F$2, ) -> 1500 | G8: =E8*$G$2 -> 2250 | H8: =E8+F8+G8 -> 18750 | I8: =H8*$I$2 -> 2437.5 | J8: =H8-I8 -> 16312.5 | K8: жен | L8: =LOOKUP(M8,Справочники!$B$2:$B$35,Справочники!$A$2:$A$35) -> Управление | M8: Референт | N8: среднее специальное | O8: 39956 | P8: =DATEDIF(O8, TODAY(),"Y") -> 13 | Q8: 30254 | R8: =DATEDIF(Q8, TODAY(),"Y") -> 40 | S8: =LOOKUP(L8,Справочники!$F$2:$F$10,Справочники!$H$2:$H$10) -> +7(8332)64-32-18
A9: 150 | B9: Бычкова | C9: Людмила | D9: Петровна | E9: =LOOKUP(M9,Справочники!$B$2:$B$35,Справочники!$C$2:$C$35) -> 16000 | F9: =IF(P9>=5, E9*$F$2, ) -> 1600 | G9: =E9*$G$2 -> 2400 | H9: =E9+F9+G9 -> 20000 | I9: =H9*$I$2 -> 2600 | J9: =H9-I9 -> 17400 | K9: жен | L9: =LOOKUP(M9,Справочники!$B$2:$B$35,Справочники!$A$2:$A$35) -> Редакторский отдел | M9: Переводчик | N9: высшее | O9: 34714 | P9: =DATEDIF(O9, TODAY(),"Y") -> 27 | Q9: 22250 | R9: =DATEDIF(Q9, TODAY(),"Y") -> 61 | S9: =LOOKUP(L9,Справочники!$F$2:$F$10,Справочники!$H$2:$H$10) -> +7(8332)64-32-01
A10: 109 | B10: Васильев | C10: Леонид | D10: Сергеевич | E10: =LOOKUP(M10,Справочники!$B$2:$B$35,Справочники!$C$2:$C$35) -> 28000 | F10: =IF(P10>=5, E10*$F$2, ) -> 2800 | G10: =E10*$G$2 -> 4200 | H10: =E10+F10+G10 -> 35000 | I10: =H10*$I$2 -> 4550 | J10: =H10-I10 -> 30450 | K10: муж | L10: =LOOKUP(M10,Справочники!$B$2:$B$35,Справочники!$A$2:$A$35) -> Управление | M10: Зам. директора | N10: высшее | O10: 39103 | P10: =DATEDIF(O10, TODAY(),"Y") -> 15 | Q10: 27786 | R10: =DATEDIF(Q10, TODAY(),"Y") -> 46 | S10: =LOOKUP(L10,Справочники!$F$2:$F$10,Справочники!$H$2:$H$10) -> +7(8332)64-32-18
A11: 102 | B11: Вербицкая | C11: Елена | D11: Вадимовна | E11: =LOOKUP(M11,Справочники!$B$2:$B$35,Справочники!$C$2:$C$35) -> 20000 | F11: =IF(P11>=5, E11*$F$2, ) -> 2000 | G11: =E11*$G$2 -> 3000 | H11: =E11+F11+G11 -> 25000 | I11: =H11*$I$2 -> 3250 | J11: =H11-I11 -> 21750 | K11: жен | L11: =LOOKUP(M11,Справочники!$B$2:$B$35,Справочники!$A$2:$A$35) -> Бухгалтерия | M11: Главный бухгалтер | N11: высшее | O11: 34380 | P11: =DATEDIF(O11, TODAY(),"Y") -> 28 | Q11: 25186 | R11: =DATEDIF(Q11, TODAY(),"Y") -> 53 | S11: =LOOKUP(L11,Справочники!$F$2:$F$10,Справочники!$H$2:$H$10) -> +7(8332)64-32-01
A12: 143 | B12: Веселов | C12: Аркадий | D12: Тимофеевич | E12: =LOOKUP(M12,Справочники!$B$2:$B$35,Справочники!$C$2:$C$35) -> 11000 | F12: =IF(P12>=5, E12*$F$2, ) -> 1100 | G12: =E12*$G$2 -> 1650 | H12: =E12+F12+G12 -> 13750 | I12: =H12*$I$2 -> 1787.5 | J12: =H12-I12 -> 11962.5 | K12: муж | L12: =LOOKUP(M12,Справочники!$B$2:$B$35,Справочники!$A$2:$A$35) -> Склад | M12: Грузчик | N12: среднее | O12: 42016 | P12: =DATEDIF(O12, TODAY(),"Y") -> 7 | Q12: 30232 | R12: =DATEDIF(Q12, TODAY(),"Y") -> 40 | S12: =LOOKUP(L12,Справочники!$F$2:$F$10,Справочники!$H$2:$H$10) -> +7(8332)64-32-23
A13: 134 | B13: Володина | C13: Валентина | D13: Кириловна | E13: =LOOKUP(M13,Справочники!$B$2:$B$35,Справочники!$C$2:$C$35) -> 20000 | F13: =IF(P13>=5, E13*$F$2, ) -> 2000 | G13: =E13*$G$2 -> 3000 | H13: =E13+F13+G13 -> 25000 | I13: =H13*$I$2 -> 3250 | J13: =H13-I13 -> 21750 | K13: жен | L13: =LOOKUP(M13,Справочники!$B$2:$B$35,Справочники!$A$2:$A$35) -> Технологический отдел | M13: Художник | N13: высшее | O13: 35208 | P13: =DATEDIF(O13, TODAY(),"Y") -> 26 | Q13: 25186 | R13: =DATEDIF(Q13, TODAY(),"Y") -> 53 | S13: =LOOKUP(L13,Справочники!$F$2:$F$10,Справочники!$H$2:$H$10) -> +7(8332)64-32-18
A14: 142 | B14: Георгиева | C14: Ульяна | D14: Сергеевна | E14: =LOOKUP(M14,Справочники!$B$2:$B$35,Справочники!$C$2:$C$35) -> 15000 | F14: =IF(P14>=5, E14*$F$2, ) -> 1500 | G14: =E14*$G$2 -> 2250 | H14: =E14+F14+G14 -> 18750 | I14: =H14*$I$2 -> 2437.5 | J14: =H14-I14 -> 16312.5 | K14: жен | L14: =LOOKUP(M14,Справочники!$B$2:$B$35,Справочники!$A$2:$A$35) -> Склад | M14: Кладовщик | N14: среднее | O14: 34955 | P14: =DATEDIF(O14, TODAY(),"Y") -> 27 | Q14: 24134 | R14: =DATEDIF(Q14, TODAY(),"Y") -> 56 | S14: =LOOKUP(L14,Справочники!$F$2:$F$10,Справочники!$H$2:$H$10) -> +7(8332)64-32-23
A15: 114 | B15: Горбачева | C15: Клавдия | D15: Валериевна | E15: =LOOKUP(M15,Справочники!$B$2:$B$35,Справочники!$C$2:$C$35) -> 22000 | F15: =IF(P15>=5, E15*$F$2, ) -> 0 | G15: =E15*$G$2 -> 3300 | H15: =E15+F15+G15 -> 25300 | I15: =H15*$I$2 -> 3289 | J15: =H15-I15 -> 22011 | K15: жен | L15: =LOOKUP(M15,Справочники!$B$2:$B$35,Справочники!$A$2:$A$35) -> Технологический отдел | M15: Главный технолог | N15: высшее | O15: 43356 | P15: =DATEDIF(O15, TODAY(),"Y") -> 4 | Q15: 24300 | R15: =DATEDIF(Q15, TODAY(),"Y") -> 56 | S15: =LOOKUP(L15,Справочники!$F$2:$F$10,Справочники!$H$2:$H$10) -> +7(8332)64-32-18
... A67: 125 | B67: Юматова | C67: Татьяна | D67: Сергеевна | E67: =LOOKUP(M67,Справочники!$B$2:$B$35,Справочники!$C$2:$C$35) -> 12000 | F67: =IF(P67>=5, E67*$F$2, ) -> 1200 | G67: =E67*$G$2 -> 1800 | H67: =E67+F67+G67 -> 15000 | I67: =H67*$I$2 -> 1950 | J67: =H67-I67 -> 13050 | K67: жен | L67: =LOOKUP(M67,Справочники!$B$2:$B$35,Справочники!$A$2:$A$35) -> Технологический отдел | M67: Верстальщик | N67: среднее | O67: 35290 | P67: =DATEDIF(O67, TODAY(),"Y") -> 26 | Q67: 22065 | R67: =DATEDIF(Q67, TODAY(),"Y") -> 62 | S67: =LOOKUP(L67,Справочники!$F$2:$F$10,Справочники!$H$2:$H$10) -> +7(8332)64-32-18
I68: =SUM(I4:I67) -> 168616.5 | J68: =SUM(J4:J67) -> 1128433.5
D69: ИТОГО:
B72: =MAX(J4:J67) -> 38062.5 | C72: - максимальная сумма к выдаче
B73: =MIN(I4:I67) -> 1644.5 | C73: - минимальный налог
B74: =AVERAGE(E4:E67) -> 16296.875 | C74: - средний оклад
B75: =COUNTIF(F4:F67, ">0") -> 60 | C75: - количество сотрудников, не получающих премию
B76: =SUMIF(F4:F67, ">0", I4:I67) -> 158600 | C76: - суммарный подоходный налог сотрудников, получающих премию
B77: =SUMIFS( E4:E67, F4:F67, "=0", E4:E67, ">15000") -> 44000 | C77: - суммарные оклады сотрудников, не получающих премию, и оклады которых превышают 15 000 руб.

Sheet Ноябрь
A1: Ведомость начисления заработной платы | I1: за октябрь 2019 | S1: Рабочий телефон
F2: 0.15 | G2: 0.15 | I2: 0.13 | S2: Рабочий телефон
A3: Табельный номер | B3: Фамилия | C3: Имя | D3: Отчество | E3: Оклад | F3: Премия | G3: Районный коэффициент | H3: Начислено | I3: НДФЛ | J3: К выдаче | K3: Пол | L3: Отдел | M3: Должность | N3: Образование | O3: Дата найма | P3: Стаж | Q3: Дата рождения | R3: Возраст | S3: Рабочий телефон
A4: 101 | B4: Айдарпашич | C4: Амина | D4: Александровна | E4: =LOOKUP(M4,Справочники!$B$2:$B$35,Справочники!$C$2:$C$35) -> 12000 | F4: =IF(P4>=5, E4*$F$2, ) -> 1800 | G4: =E4*$G$2 -> 1800 | H4: =E4+F4+G4 -> 15600 | I4: =H4*$I$2 -> 2028 | J4: =H4-I4 -> 13572 | K4: жен | L4: =LOOKUP(M4,Справочники!$B$2:$B$35,Справочники!$A$2:$A$35) -> Бухгалтерия | M4: Бухгалтер | N4: высшее | O4: 38944 | P4: =DATEDIF(O4, TODAY(),"Y") -> 16 | Q4: 30198 | R4: =DATEDIF(Q4, TODAY(),"Y") -> 40 | S4: =LOOKUP(L4,Справочники!$F$2:$F$10,Справочники!$H$2:$H$10) -> +7(8332)64-32-01
A5: 105 | B5: Алеев | C5: Леонид | D5: Иванович | E5: =LOOKUP(M5,Справочники!$B$2:$B$35,Справочники!$C$2:$C$35) -> 17000 | F5: =IF(P5>=5, E5*$F$2, ) -> 2550 | G5: =E5*$G$2 -> 2550 | H5: =E5+F5+G5 -> 22100 | I5: =H5*$I$2 -> 2873 | J5: =H5-I5 -> 19227 | K5: муж | L5: =LOOKUP(M5,Справочники!$B$2:$B$35,Справочники!$A$2:$A$35) -> Бухгалтерия | M5: Зам. гл. бухгалтера | N5: высшее | O5: 41165 | P5: =DATEDIF(O5, TODAY(),"Y") -> 10 | Q5: 31196 | R5: =DATEDIF(Q5, TODAY(),"Y") -> 37 | S5: =LOOKUP(L5,Справочники!$F$2:$F$10,Справочники!$H$2:$H$10) -> +7(8332)64-32-01
A6: 130 | B6: Арбузова | C6: Маргарита | D6: Ивановна | E6: =LOOKUP(M6,Справочники!$B$2:$B$35,Справочники!$C$2:$C$35) -> 15000 | F6: =IF(P6>=5, E6*$F$2, ) -> 2250 | G6: =E6*$G$2 -> 2250 | H6: =E6+F6+G6 -> 19500 | I6: =H6*$I$2 -> 2535 | J6: =H6-I6 -> 16965 | K6: жен | L6: =LOOKUP(M6,Справочники!$B$2:$B$35,Справочники!$A$2:$A$35) -> Управление | M6: Референт | N6: неполное высшее | O6: 42765 | P6: =DATEDIF(O6, TODAY(),"Y") -> 5 | Q6: 34714 | R6: =DATEDIF(Q6, TODAY(),"Y") -> 27 | S6: =LOOKUP(L6,Справочники!$F$2:$F$10,Справочники!$H$2:$H$10) -> +7(8332)64-32-18
A7: 139 | B7: Белозерова | C7: Ольга | D7: Владимировна | E7: =LOOKUP(M7,Справочники!$B$2:$B$35,Справочники!$C$2:$C$35) -> 15000 | F7: =IF(P7>=5, E7*$F$2, ) -> 2250 | G7: =E7*$G$2 -> 2250 | H7: =E7+F7+G7 -> 19500 | I7: =H7*$I$2 -> 2535 | J7: =H7-I7 -> 16965 | K7: жен | L7: =LOOKUP(M7,Справочники!$B$2:$B$35,Справочники!$A$2:$A$35) -> Управление | M7: Референт | N7: среднее специальное | O7: 41697 | P7: =DATEDIF(O7, TODAY(),"Y") -> 8 | Q7: 33022 | R7: =DATEDIF(Q7, TODAY(),"Y") -> 32 | S7: =LOOKUP(L7,Справочники!$F$2:$F$10,Справочники!$H$2:$H$10) -> +7(8332)64-32-18
A8: 107 | B8: Богуславская | C8: Дарья | D8: Вячеславовна | E8: =LOOKUP(M8,Справочники!$B$2:$B$35,Справочники!$C$2:$C$35) -> 15000 | F8: =IF(P8>=5, E8*$F$2, ) -> 2250 | G8: =E8*$G$2 -> 2250 | H8: =E8+F8+G8 -> 19500 | I8: =H8*$I$2 -> 2535 | J8: =H8-I8 -> 16965 | K8: жен | L8: =LOOKUP(M8,Справочники!$B$2:$B$35,Справочники!$A$2:$A$35) -> Управление | M8: Референт | N8: среднее специальное | O8: 39956 | P8: =DATEDIF(O8, TODAY(),"Y") -> 13 | Q8: 30254 | R8: =DATEDIF(Q8, TODAY(),"Y") -> 40 | S8: =LOOKUP(L8,Справочники!$F$2:$F$10,Справочники!$H$2:$H$10) -> +7(8332)64-32-18
A9: 150 | B9: Бычкова | C9: Людмила | D9: Петровна | E9: =LOOKUP(M9,Справочники!$B$2:$B$35,Справочники!$C$2:$C$35) -> 16000 | F9: =IF(P9>=5, E9*$F$2, ) -> 2400 | G9: =E9*$G$2 -> 2400 | H9: =E9+F9+G9 -> 20800 | I9: =H9*$I$2 -> 2704 | J9: =H9-I9 -> 18096 | K9: жен | L9: =LOOKUP(M9,Справочники!$B$2:$B$35,Справочники!$A$2:$A$35) -> Редакторский отдел | M9: Переводчик | N9: высшее | O9: 34714 | P9: =DATEDIF(O9, TODAY(),"Y") -> 27 | Q9: 22250 | R9: =DATEDIF(Q9, TODAY(),"Y") -> 61 | S9: =LOOKUP(L9,Справочники!$F$2:$F$10,Справочники!$H$2:$H$10) -> +7(8332)64-32-01
A10: 109 | B10: Васильев | C10: Леонид | D10: Сергеевич | E10: =LOOKUP(M10,Справочники!$B$2:$B$35,Справочники!$C$2:$C$35) -> 28000 | F10: =IF(P10>=5, E10*$F$2, ) -> 4200 | G10: =E10*$G$2 -> 4200 | H10: =E10+F10+G10 -> 36400 | I10: =H10*$I$2 -> 4732 | J10: =H10-I10 -> 31668 | K10: муж | L10: =LOOKUP(M10,Справочники!$B$2:$B$35,Справочники!$A$2:$A$35) -> Управление | M10: Зам. директора | N10: высшее | O10: 39103 | P10: =DATEDIF(O10, TODAY(),"Y") -> 15 | Q10: 27786 | R10: =DATEDIF(Q10, TODAY(),"Y") -> 46 | S10: =LOOKUP(L10,Справочники!$F$2:$F$10,Справочники!$H$2:$H$10) -> +7(8332)64-32-18
A11: 102 | B11: Вербицкая | C11: Елена | D11: Вадимовна | E11: =LOOKUP(M11,Справочники!$B$2:$B$35,Справочники!$C$2:$C$35) -> 20000 | F11: =IF(P11>=5, E11*$F$2, ) -> 3000 | G11: =E11*$G$2 -> 3000 | H11: =E11+F11+G11 -> 26000 | I11: =H11*$I$2 -> 3380 | J11: =H11-I11 -> 22620 | K11: жен | L11: =LOOKUP(M11,Справочники!$B$2:$B$35,Справочники!$A$2:$A$35) -> Бухгалтерия | M11: Главный бухгалтер | N11: высшее | O11: 34380 | P11: =DATEDIF(O11, TODAY(),"Y") -> 28 | Q11: 25186 | R11: =DATEDIF(Q11, TODAY(),"Y") -> 53 | S11: =LOOKUP(L11,Справочники!$F$2:$F$10,Справочники!$H$2:$H$10) -> +7(8332)64-32-01
A12: 143 | B12: Веселов | C12: Аркадий | D12: Тимофеевич | E12: =LOOKUP(M12,Справочники!$B$2:$B$35,Справочники!$C$2:$C$35) -> 11000 | F12: =IF(P12>=5, E12*$F$2, ) -> 1650 | G12: =E12*$G$2 -> 1650 | H12: =E12+F12+G12 -> 14300 | I12: =H12*$I$2 -> 1859 | J12: =H12-I12 -> 12441 | K12: муж | L12: =LOOKUP(M12,Справочники!$B$2:$B$35,Справочники!$A$2:$A$35) -> Склад | M12: Грузчик | N12: среднее | O12: 42016 | P12: =DATEDIF(O12, TODAY(),"Y") -> 7 | Q12: 30232 | R12: =DATEDIF(Q12, TODAY(),"Y") -> 40 | S12: =LOOKUP(L12,Справочники!$F$2:$F$10,Справочники!$H$2:$H$10) -> +7(8332)64-32-23
A13: 134 | B13: Володина | C13: Валентина | D13: Кириловна | E13: =LOOKUP(M13,Справочники!$B$2:$B$35,Справочники!$C$2:$C$35) -> 20000 | F13: =IF(P13>=5, E13*$F$2, ) -> 3000 | G13: =E13*$G$2 -> 3000 | H13: =E13+F13+G13 -> 26000 | I13: =H13*$I$2 -> 3380 | J13: =H13-I13 -> 22620 | K13: жен | L13: =LOOKUP(M13,Справочники!$B$2:$B$35,Справочники!$A$2:$A$35) -> Технологический отдел | M13: Художник | N13: высшее | O13: 35208 | P13: =DATEDIF(O13, TODAY(),"Y") -> 26 | Q13: 25186 | R13: =DATEDIF(Q13, TODAY(),"Y") -> 53 | S13: =LOOKUP(L13,Справочники!$F$2:$F$10,Справочники!$H$2:$H$10) -> +7(8332)64-32-18
A14: 142 | B14: Георгиева | C14: Ульяна | D14: Сергеевна | E14: =LOOKUP(M14,Справочники!$B$2:$B$35,Справочники!$C$2:$C$35) -> 15000 | F14: =IF(P14>=5, E14*$F$2, ) -> 2250 | G14: =E14*$G$2 -> 2250 | H14: =E14+F14+G14 -> 19500 | I14: =H14*$I$2 -> 2535 | J14: =H14-I14 -> 16965 | K14: жен | L14: =LOOKUP(M14,Справочники!$B$2:$B$35,Справочники!$A$2:$A$35) -> Склад | M14: Кладовщик | N14: среднее | O14: 34955 | P14: =DATEDIF(O14, TODAY(),"Y") -> 27 | Q14: 24134 | R14: =DATEDIF(Q14, TODAY(),"Y") -> 56 | S14: =LOOKUP(L14,Справочники!$F$2:$F$10,Справочники!$H$2:$H$10) -> +7(8332)64-32-23
A15: 114 | B15: Горбачева | C15: Клавдия | D15: Валериевна | E15: =LOOKUP(M15,Справочники!$B$2:$B$35,Справочники!$C$2:$C$35) -> 22000 | F15: =IF(P15>=5, E15*$F$2, ) -> 0 | G15: =E15*$G$2 -> 3300 | H15: =E15+F15+G15 -> 25300 | I15: =H15*$I$2 -> 3289 | J15: =H15-I15 -> 22011 | K15: жен | L15: =LOOKUP(M15,Справочники!$B$2:$B$35,Справочники!$A$2:$A$35) -> Технологический отдел | M15: Главный технолог | N15: высшее | O15: 43356 | P15: =DATEDIF(O15, TODAY(),"Y") -> 4 | Q15: 24300 | R15: =DATEDIF(Q15, TODAY(),"Y") -> 56 | S15: =LOOKUP(L15,Справочники!$F$2:$F$10,Справочники!$H$2:$H$10) -> +7(8332)64-32-18
... A67: 125 | B67: Юматова | C67: Татьяна | D67: Сергеевна | E67: =LOOKUP(M67,Справочники!$B$2:$B$35,Справочники!$C$2:$C$35) -> 12000 | F67: =IF(P67>=5, E67*$F$2, ) -> 1800 | G67: =E67*$G$2 -> 1800 | H67: =E67+F67+G67 -> 15600 | I67: =H67*$I$2 -> 2028 | J67: =H67-I67 -> 13572 | K67: жен | L67: =LOOKUP(M67,Справочники!$B$2:$B$35,Справочники!$A$2:$A$35) -> Технологический отдел | M67: Верстальщик | N67: среднее | O67: 35290 | P67: =DATEDIF(O67, TODAY(),"Y") -> 26 | Q67: 22065 | R67: =DATEDIF(Q67, TODAY(),"Y") -> 62 | S67: =LOOKUP(L67,Справочники!$F$2:$F$10,Справочники!$H$2:$H$10) -> +7(8332)64-32-18
I68: =SUM(I4:I67) -> 174960.5 | J68: =SUM(J4:J67) -> 1170889.5
D69: ИТОГО:
B72: =MAX(J4:J67) -> 39585 | C72: - максимальная сумма к выдаче
B73: =MIN(I4:I67) -> 1644.5 | C73: - минимальный налог
B74: =AVERAGE(E4:E67) -> 16296.875 | C74: - средний оклад
B75: =COUNTIF(F4:F67, ">0") -> 60 | C75: - количество сотрудников, не получающих премию
B76: =SUMIF(F4:F67, ">0", I4:I67) -> 164944 | C76: - суммарный подоходный налог сотрудников, получающих премию
B77: =SUMIFS( E4:E67, F4:F67, "=0", E4:E67, ">15000") -> 44000 | C77: - суммарные оклады сотрудников, не получающих премию, и оклады которых превышают 15 000 руб.

Sheet Декабрь
A1: Ведомость начисления заработной платы | I1: за октябрь 2019 | S1: Рабочий телефон
F2: 0.53759009 | G2: 0.15 | I2: 0.13 | S2: Рабочий телефон
A3: Табельный номер | B3: Фамилия | C3: Имя | D3: Отчество | E3: Оклад | F3: Премия | G3: Районный коэффициент | H3: Начислено | I3: НДФЛ | J3: К выдаче | K3: Пол | L3: Отдел | M3: Должность | N3: Образование | O3: Дата найма | P3: Стаж | Q3: Дата рождения | R3: Возраст | S3: Рабочий телефон
A4: 101 | B4: Айдарпашич | C4: Амина | D4: Александровна | E4: =LOOKUP(M4,Справочники!$B$2:$B$35,Справочники!$C$2:$C$35) -> 12000 | F4: =IF(P4>=5, E4*$F$2, ) -> 6451.0811 | G4: =E4*$G$2 -> 1800 | H4: =E4+F4+G4 -> 20251.081 | I4: =H4*$I$2 -> 2632.6405 | J4: =H4-I4 -> 17618.441 | K4: жен | L4: =LOOKUP(M4,Справочники!$B$2:$B$35,Справочники!$A$2:$A$35) -> Бухгалтерия | M4: Бухгалтер | N4: высшее | O4: 38944 | P4: =DATEDIF(O4, TODAY(),"Y") -> 16 | Q4: 30198 | R4: =DATEDIF(Q4, TODAY(),"Y") -> 40 | S4: =LOOKUP(L4,Справочники!$F$2:$F$10,Справочники!$H$2:$H$10) -> +7(8332)64-32-01
A5: 105 | B5: Алеев | C5: Леонид | D5: Иванович | E5: =LOOKUP(M5,Справочники!$B$2:$B$35,Справочники!$C$2:$C$35) -> 17000 | F5: =IF(P5>=5, E5*$F$2, ) -> 9139.0316 | G5: =E5*$G$2 -> 2550 | H5: =E5+F5+G5 -> 28689.032 | I5: =H5*$I$2 -> 3729.5741 | J5: =H5-I5 -> 24959.457 | K5: муж | L5: =LOOKUP(M5,Справочники!$B$2:$B$35,Справочники!$A$2:$A$35) -> Бухгалтерия | M5: Зам. гл. бухгалтера | N5: высшее | O5: 41165 | P5: =DATEDIF(O5, TODAY(),"Y") -> 10 | Q5: 31196 | R5: =DATEDIF(Q5, TODAY(),"Y") -> 37 | S5: =LOOKUP(L5,Справочники!$F$2:$F$10,Справочники!$H$2:$H$10) -> +7(8332)64-32-01
A6: 130 | B6: Арбузова | C6: Маргарита | D6: Ивановна | E6: =LOOKUP(M6,Справочники!$B$2:$B$35,Справочники!$C$2:$C$35) -> 15000 | F6: =IF(P6>=5, E6*$F$2, ) -> 8063.8514 | G6: =E6*$G$2 -> 2250 | H6: =E6+F6+G6 -> 25313.851 | I6: =H6*$I$2 -> 3290.8007 | J6: =H6-I6 -> 22023.051 | K6: жен | L6: =LOOKUP(M6,Справочники!$B$2:$B$35,Справочники!$A$2:$A$35) -> Управление | M6: Референт | N6: неполное высшее | O6: 42765 | P6: =DATEDIF(O6, TODAY(),"Y") -> 5 | Q6: 34714 | R6: =DATEDIF(Q6, TODAY(),"Y") -> 27 | S6: =LOOKUP(L6,Справочники!$F$2:$F$10,Справочники!$H$2:$H$10) -> +7(8332)64-32-18
A7: 139 | B7: Белозерова | C7: Ольга | D7: Владимировна | E7: =LOOKUP(M7,Справочники!$B$2:$B$35,Справочники!$C$2:$C$35) -> 15000 | F7: =IF(P7>=5, E7*$F$2, ) -> 8063.8514 | G7: =E7*$G$2 -> 2250 | H7: =E7+F7+G7 -> 25313.851 | I7: =H7*$I$2 -> 3290.8007 | J7: =H7-I7 -> 22023.051 | K7: жен | L7: =LOOKUP(M7,Справочники!$B$2:$B$35,Справочники!$A$2:$A$35) -> Управление | M7: Референт | N7: среднее специальное | O7: 41697 | P7: =DATEDIF(O7, TODAY(),"Y") -> 8 | Q7: 33022 | R7: =DATEDIF(Q7, TODAY(),"Y") -> 32 | S7: =LOOKUP(L7,Справочники!$F$2:$F$10,Справочники!$H$2:$H$10) -> +7(8332)64-32-18
A8: 107 | B8: Богуславская | C8: Дарья | D8: Вячеславовна | E8: =LOOKUP(M8,Справочники!$B$2:$B$35,Справочники!$C$2:$C$35) -> 15000 | F8: =IF(P8>=5, E8*$F$2, ) -> 8063.8514 | G8: =E8*$G$2 -> 2250 | H8: =E8+F8+G8 -> 25313.851 | I8: =H8*$I$2 -> 3290.8007 | J8: =H8-I8 -> 22023.051 | K8: жен | L8: =LOOKUP(M8,Справочники!$B$2:$B$35,Справочники!$A$2:$A$35) -> Управление | M8: Референт | N8: среднее специальное | O8: 39956 | P8: =DATEDIF(O8, TODAY(),"Y") -> 13 | Q8: 30254 | R8: =DATEDIF(Q8, TODAY(),"Y") -> 40 | S8: =LOOKUP(L8,Справочники!$F$2:$F$10,Справочники!$H$2:$H$10) -> +7(8332)64-32-18
A9: 150 | B9: Бычкова | C9: Людмила | D9: Петровна | E9: =LOOKUP(M9,Справочники!$B$2:$B$35,Справочники!$C$2:$C$35) -> 16000 | F9: =IF(P9>=5, E9*$F$2, ) -> 8601.4415 | G9: =E9*$G$2 -> 2400 | H9: =E9+F9+G9 -> 27001.441 | I9: =H9*$I$2 -> 3510.1874 | J9: =H9-I9 -> 23491.254 | K9: жен | L9: =LOOKUP(M9,Справочники!$B$2:$B$35,Справочники!$A$2:$A$35) -> Редакторский отдел | M9: Переводчик | N9: высшее | O9: 34714 | P9: =DATEDIF(O9, TODAY(),"Y") -> 27 | Q9: 22250 | R9: =DATEDIF(Q9, TODAY(),"Y") -> 61 | S9: =LOOKUP(L9,Справочники!$F$2:$F$10,Справочники!$H$2:$H$10) -> +7(8332)64-32-01
A10: 109 | B10: Васильев | C10: Леонид | D10: Сергеевич | E10: =LOOKUP(M10,Справочники!$B$2:$B$35,Справочники!$C$2:$C$35) -> 28000 | F10: =IF(P10>=5, E10*$F$2, ) -> 15052.523 | G10: =E10*$G$2 -> 4200 | H10: =E10+F10+G10 -> 47252.523 | I10: =H10*$I$2 -> 6142.8279 | J10: =H10-I10 -> 41109.695 | K10: муж | L10: =LOOKUP(M10,Справочники!$B$2:$B$35,Справочники!$A$2:$A$35) -> Управление | M10: Зам. директора | N10: высшее | O10: 39103 | P10: =DATEDIF(O10, TODAY(),"Y") -> 15 | Q10: 27786 | R10: =DATEDIF(Q10, TODAY(),"Y") -> 46 | S10: =LOOKUP(L10,Справочники!$F$2:$F$10,Справочники!$H$2:$H$10) -> +7(8332)64-32-18
A11: 102 | B11: Вербицкая | C11: Елена | D11: Вадимовна | E11: =LOOKUP(M11,Справочники!$B$2:$B$35,Справочники!$C$2:$C$35) -> 20000 | F11: =IF(P11>=5, E11*$F$2, ) -> 10751.802 | G11: =E11*$G$2 -> 3000 | H11: =E11+F11+G11 -> 33751.802 | I11: =H11*$I$2 -> 4387.7342 | J11: =H11-I11 -> 29364.068 | K11: жен | L11: =LOOKUP(M11,Справочники!$B$2:$B$35,Справочники!$A$2:$A$35) -> Бухгалтерия | M11: Главный бухгалтер | N11: высшее | O11: 34380 | P11: =DATEDIF(O11, TODAY(),"Y") -> 28 | Q11: 25186 | R11: =DATEDIF(Q11, TODAY(),"Y") -> 53 | S11: =LOOKUP(L11,Справочники!$F$2:$F$10,Справочники!$H$2:$H$10) -> +7(8332)64-32-01
A12: 143 | B12: Веселов | C12: Аркадий | D12: Тимофеевич | E12: =LOOKUP(M12,Справочники!$B$2:$B$35,Справочники!$C$2:$C$35) -> 11000 | F12: =IF(P12>=5, E12*$F$2, ) -> 5913.491 | G12: =E12*$G$2 -> 1650 | H12: =E12+F12+G12 -> 18563.491 | I12: =H12*$I$2 -> 2413.2538 | J12: =H12-I12 -> 16150.237 | K12: муж | L12: =LOOKUP(M12,Справочники!$B$2:$B$35,Справочники!$A$2:$A$35) -> Склад | M12: Грузчик | N12: среднее | O12: 42016 | P12: =DATEDIF(O12, TODAY(),"Y") -> 7 | Q12: 30232 | R12: =DATEDIF(Q12, TODAY(),"Y") -> 40 | S12: =LOOKUP(L12,Справочники!$F$2:$F$10,Справочники!$H$2:$H$10) -> +7(8332)64-32-23
A13: 134 | B13: Володина | C13: Валентина | D13: Кириловна | E13: =LOOKUP(M13,Справочники!$B$2:$B$35,Справочники!$C$2:$C$35) -> 20000 | F13: =IF(P13>=5, E13*$F$2, ) -> 10751.802 | G13: =E13*$G$2 -> 3000 | H13: =E13+F13+G13 -> 33751.802 | I13: =H13*$I$2 -> 4387.7342 | J13: =H13-I13 -> 29364.068 | K13: жен | L13: =LOOKUP(M13,Справочники!$B$2:$B$35,Справочники!$A$2:$A$35) -> Технологический отдел | M13: Художник | N13: высшее | O13: 35208 | P13: =DATEDIF(O13, TODAY(),"Y") -> 26 | Q13: 25186 | R13: =DATEDIF(Q13, TODAY(),"Y") -> 53 | S13: =LOOKUP(L13,Справочники!$F$2:$F$10,Справочники!$H$2:$H$10) -> +7(8332)64-32-18
A14: 142 | B14: Георгиева | C14: Ульяна | D14: Сергеевна | E14: =LOOKUP(M14,Справочники!$B$2:$B$35,Справочники!$C$2:$C$35) -> 15000 | F14: =IF(P14>=5, E14*$F$2, ) -> 8063.8514 | G14: =E14*$G$2 -> 2250 | H14: =E14+F14+G14 -> 25313.851 | I14: =H14*$I$2 -> 3290.8007 | J14: =H14-I14 -> 22023.051 | K14: жен | L14: =LOOKUP(M14,Справочники!$B$2:$B$35,Справочники!$A$2:$A$35) -> Склад | M14: Кладовщик | N14: среднее | O14: 34955 | P14: =DATEDIF(O14, TODAY(),"Y") -> 27 | Q14: 24134 | R14: =DATEDIF(Q14, TODAY(),"Y") -> 56 | S14: =LOOKUP(L14,Справочники!$F$2:$F$10,Справочники!$H$2:$H$10) -> +7(8332)64-32-23
A15: 114 | B15: Горбачева | C15: Клавдия | D15: Валериевна | E15: =LOOKUP(M15,Справочники!$B$2:$B$35,Справочники!$C$2:$C$35) -> 22000 | F15: =IF(P15>=5, E15*$F$2, ) -> 0 | G15: =E15*$G$2 -> 3300 | H15: =E15+F15+G15 -> 25300 | I15: =H15*$I$2 -> 3289 | J15: =H15-I15 -> 22011 | K15: жен | L15: =LOOKUP(M15,Справочники!$B$2:$B$35,Справочники!$A$2:$A$35) -> Технологический отдел | M15: Главный технолог | N15: высшее | O15: 43356 | P15: =DATEDIF(O15, TODAY(),"Y") -> 4 | Q15: 24300 | R15: =DATEDIF(Q15, TODAY(),"Y") -> 56 | S15: =LOOKUP(L15,Справочники!$F$2:$F$10,Справочники!$H$2:$H$10) -> +7(8332)64-32-18
... A67: 125 | B67: Юматова | C67: Татьяна | D67: Сергеевна | E67: =LOOKUP(M67,Справочники!$B$2:$B$35,Справочники!$C$2:$C$35) -> 12000 | F67: =IF(P67>=5, E67*$F$2, ) -> 6451.0811 | G67: =E67*$G$2 -> 1800 | H67: =E67+F67+G67 -> 20251.081 | I67: =H67*$I$2 -> 2632.6405 | J67: =H67-I67 -> 17618.441 | K67: жен | L67: =LOOKUP(M67,Справочники!$B$2:$B$35,Справочники!$A$2:$A$35) -> Технологический отдел | M67: Верстальщик | N67: среднее | O67: 35290 | P67: =DATEDIF(O67, TODAY(),"Y") -> 26 | Q67: 22065 | R67: =DATEDIF(Q67, TODAY(),"Y") -> 62 | S67: =LOOKUP(L67,Справочники!$F$2:$F$10,Справочники!$H$2:$H$10) -> +7(8332)64-32-18
I68: =SUM(I4:I67) -> 224137.93 | J68: =SUM(J4:J67) -> 1500000
D69: ИТОГО:
B72: =MAX(J4:J67) -> 51387.118 | C72: - максимальная сумма к выдаче
B73: =MIN(I4:I67) -> 1644.5 | C73: - минимальный налог
B74: =AVERAGE(E4:E67) -> 16296.875 | C74: - средний оклад
B75: =COUNTIF(F4:F67, ">0") -> 60 | C75: - количество сотрудников, не получающих премию
B76: =SUMIF(F4:F67, ">0", I4:I67) -> 214121.43 | C76: - суммарный подоходный налог сотрудников, получающих премию
B77: =SUMIFS( E4:E67, F4:F67, "=0", E4:E67, ">15000") -> 44000 | C77: - суммарные оклады сотрудников, не получающих премию, и оклады которых превышают 15 000 руб.

Sheet 2.1
A1: Табельный номер | B1: Фамилия | C1: Имя | D1: Отчество | E1: Пол | F1: Отдел | G1: Должность | H1: Оклад | I1: Образование | J1: Дата найма | K1: Дата рождения | L1: Стаж | M1: Возраст | N1: Рабочий телефон
A2: 101 | B2: Айдарпашич | C2: Амина | D2: Александровна | E2: жен | F2: =LOOKUP(G2,Справочники!$B$2:$B$35,Справочники!$A$2:$A$35) -> Бухгалтерия | G2: Бухгалтер | H2: =LOOKUP(G2,Справочники!$B$2:$B$35,Справочники!$C$2:$C$35) -> 12000 | I2: высшее | J2: 38944 | K2: 30198 | L2: =DATEDIF(J2, TODAY(),"Y") -> 16 | M2: =DATEDIF(K2, TODAY(),"Y") -> 40 | N2: =LOOKUP(F2,Справочники!$F$2:$F$10,Справочники!$H$2:$H$10) -> +7(8332)64-32-01
A3: 102 | B3: Вербицкая | C3: Елена | D3: Вадимовна | E3: жен | F3: =LOOKUP(G3,Справочники!$B$2:$B$35,Справочники!$A$2:$A$35) -> Бухгалтерия | G3: Главный бухгалтер | H3: =LOOKUP(G3,Справочники!$B$2:$B$35,Справочники!$C$2:$C$35) -> 20000 | I3: высшее | J3: 34380 | K3: 25186 | L3: =DATEDIF(J3, TODAY(),"Y") -> 28 | M3: =DATEDIF(K3, TODAY(),"Y") -> 53 | N3: =LOOKUP(F3,Справочники!$F$2:$F$10,Справочники!$H$2:$H$10) -> +7(8332)64-32-01
A4: 103 | B4: Иванова | C4: Людмила | D4: Петровна | E4: жен | F4: =LOOKUP(G4,Справочники!$B$2:$B$35,Справочники!$A$2:$A$35) -> Бухгалтерия | G4: Кассир | H4: =LOOKUP(G4,Справочники!$B$2:$B$35,Справочники!$C$2:$C$35) -> 12000 | I4: среднее специальное | J4: 42962 | K4: 34762 | L4: =DATEDIF(J4, TODAY(),"Y") -> 5 | M4: =DATEDIF(K4, TODAY(),"Y") -> 27 | N4: =LOOKUP(F4,Справочники!$F$2:$F$10,Справочники!$H$2:$H$10) -> +7(8332)64-32-01
A5: 104 | B5: Лобурец | C5: Диана | D5: Борисовна | E5: жен | F5: =LOOKUP(G5,Справочники!$B$2:$B$35,Справочники!$A$2:$A$35) -> Бухгалтерия | G5: Экономист | H5: =LOOKUP(G5,Справочники!$B$2:$B$35,Справочники!$C$2:$C$35) -> 15000 | I5: высшее | J5: 41530 | K5: 25346 | L5: =DATEDIF(J5, TODAY(),"Y") -> 9 | M5: =DATEDIF(K5, TODAY(),"Y") -> 53 | N5: =LOOKUP(F5,Справочники!$F$2:$F$10,Справочники!$H$2:$H$10) -> +7(8332)64-32-01
A6: 105 | B6: Алеев | C6: Леонид | D6: Иванович | E6: муж | F6: =LOOKUP(G6,Справочники!$B$2:$B$35,Справочники!$A$2:$A$35) -> Бухгалтерия | G6: Зам. гл. бухгалтера | H6: =LOOKUP(G6,Справочники!$B$2:$B$35,Справочники!$C$2:$C$35) -> 17000 | I6: высшее | J6: 41165 | K6: 31196 | L6: =DATEDIF(J6, TODAY(),"Y") -> 10 | M6: =DATEDIF(K6, TODAY(),"Y") -> 37 | N6: =LOOKUP(F6,Справочники!$F$2:$F$10,Справочники!$H$2:$H$10) -> +7(8332)64-32-01
A7: 106 | B7: Левитин | C7: Евгений | D7: Валерьянович | E7: муж | F7: =LOOKUP(G7,Справочники!$B$2:$B$35,Справочники!$A$2:$A$35) -> Бухгалтерия | G7: Бухгалтер | H7: =LOOKUP(G7,Справочники!$B$2:$B$35,Справочники!$C$2:$C$35) -> 12000 | I7: неполное высшее | J7: 42626 | K7: 31062 | L7: =DATEDIF(J7, TODAY(),"Y") -> 6 | M7: =DATEDIF(K7, TODAY(),"Y") -> 37 | N7: =LOOKUP(F7,Справочники!$F$2:$F$10,Справочники!$H$2:$H$10) -> +7(8332)64-32-01
A8: 107 | B8: Богуславская | C8: Дарья | D8: Вячеславовна | E8: жен | F8: =LOOKUP(G8,Справочники!$B$2:$B$35,Справочники!$A$2:$A$35) -> Управление | G8: Референт | H8: =LOOKUP(G8,Справочники!$B$2:$B$35,Справочники!$C$2:$C$35) -> 15000 | I8: среднее специальное | J8: 39956 | K8: 30254 | L8: =DATEDIF(J8, TODAY(),"Y") -> 13 | M8: =DATEDIF(K8, TODAY(),"Y") -> 40 | N8: =LOOKUP(F8,Справочники!$F$2:$F$10,Справочники!$H$2:$H$10) -> +7(8332)64-32-18
A9: 108 | B9: Иванов | C9: Александр | D9: Геннадиевич | E9: муж | F9: =LOOKUP(G9,Справочники!$B$2:$B$35,Справочники!$A$2:$A$35) -> Управление | G9: Директор | H9: =LOOKUP(G9,Справочники!$B$2:$B$35,Справочники!$C$2:$C$35) -> 35000 | I9: высшее | J9: 38579 | K9: 28499 | L9: =DATEDIF(J9, TODAY(),"Y") -> 17 | M9: =DATEDIF(K9, TODAY(),"Y") -> 44 | N9: =LOOKUP(F9,Справочники!$F$2:$F$10,Справочники!$H$2:$H$10) -> +7(8332)64-32-18
A10: 109 | B10: Васильев | C10: Леонид | D10: Сергеевич | E10: муж | F10: =LOOKUP(G10,Справочники!$B$2:$B$35,Справочники!$A$2:$A$35) -> Управление | G10: Зам. директора | H10: =LOOKUP(G10,Справочники!$B$2:$B$35,Справочники!$C$2:$C$35) -> 28000 | I10: высшее | J10: 39103 | K10: 27786 | L10: =DATEDIF(J10, TODAY(),"Y") -> 15 | M10: =DATEDIF(K10, TODAY(),"Y") -> 46 | N10: =LOOKUP(F10,Справочники!$F$2:$F$10,Справочники!$H$2:$H$10) -> +7(8332)64-32-18
A11: 110 | B11: Федотова | C11: Инна | D11: Николаевна | E11: жен | F11: =LOOKUP(G11,Справочники!$B$2:$B$35,Справочники!$A$2:$A$35) -> Управление | G11: Финансовый директор | H11: =LOOKUP(G11,Справочники!$B$2:$B$35,Справочники!$C$2:$C$35) -> 30000 | I11: высшее | J11: 34436 | K11: 26821 | L11: =DATEDIF(J11, TODAY(),"Y") -> 28 | M11: =DATEDIF(K11, TODAY(),"Y") -> 49 | N11: =LOOKUP(F11,Справочники!$F$2:$F$10,Справочники!$H$2:$H$10) -> +7(8332)64-32-18
A12: 111 | B12: Прохорова | C12: Татьяна | D12: Петровна | E12: жен | F12: =LOOKUP(G12,Справочники!$B$2:$B$35,Справочники!$A$2:$A$35) -> Управление | G12: Секретарь | H12: =LOOKUP(G12,Справочники!$B$2:$B$35,Справочники!$C$2:$C$35) -> 15000 | I12: неполное высшее | J12: 42960 | K12: 33207 | L12: =DATEDIF(J12, TODAY(),"Y") -> 5 | M12: =DATEDIF(K12, TODAY(),"Y") -> 31 | N12: =LOOKUP(F12,Справочники!$F$2:$F$10,Справочники!$H$2:$H$10) -> +7(8332)64-32-18
A13: 112 | B13: Максимов | C13: Андрей | D13: Леонидович | E13: муж | F13: =LOOKUP(G13,Справочники!$B$2:$B$35,Справочники!$A$2:$A$35) -> Рекламный отдел | G13: Начальник отдела | H13: =LOOKUP(G13,Справочники!$B$2:$B$35,Справочники!$C$2:$C$35) -> 22000 | I13: высшее | J13: 40966 | K13: 31390 | L13: =DATEDIF(J13, TODAY(),"Y") -> 10 | M13: =DATEDIF(K13, TODAY(),"Y") -> 36 | N13: =LOOKUP(F13,Справочники!$F$2:$F$10,Справочники!$H$2:$H$10) -> +7(8332)64-32-01
... A65: 164 | B65: Толоконникова | C65: Майя | D65: Кириловна | E65: жен | F65: =LOOKUP(G65,Справочники!$B$2:$B$35,Справочники!$A$2:$A$35) -> Транспортный отдел | G65: Диспетчер | H65: =LOOKUP(G65,Справочники!$B$2:$B$35,Справочники!$C$2:$C$35) -> 12000 | I65: среднее | J65: 43438 | K65: 34714 | L65: =DATEDIF(J65, TODAY(),"Y") -> 3 | M65: =DATEDIF(K65, TODAY(),"Y") -> 27 | N65: =LOOKUP(F65,Справочники!$F$2:$F$10,Справочники!$H$2:$H$10) -> +7(8332)64-32-18

Sheet 2.2
A1: Табельный номер | B1: Фамилия | C1: Имя | D1: Отчество | E1: Пол | F1: Отдел | G1: Должность | H1: Оклад | I1: Образование | J1: Дата найма | K1: Дата рождения | L1: Стаж | M1: Возраст | N1: Рабочий телефон
A2: 101 | B2: Айдарпашич | C2: Амина | D2: Александровна | E2: жен | F2: =LOOKUP(G2,Справочники!$B$2:$B$35,Справочники!$A$2:$A$35) -> Бухгалтерия | G2: Бухгалтер | H2: =LOOKUP(G2,Справочники!$B$2:$B$35,Справочники!$C$2:$C$35) -> 12000 | I2: высшее | J2: 38944 | K2: 30198 | L2: =DATEDIF(J2, TODAY(),"Y") -> 16 | M2: =DATEDIF(K2, TODAY(),"Y") -> 40 | N2: =LOOKUP(F2,Справочники!$F$2:$F$10,Справочники!$H$2:$H$10) -> +7(8332)64-32-01
A3: 102 | B3: Вербицкая | C3: Елена | D3: Вадимовна | E3: жен | F3: =LOOKUP(G3,Справочники!$B$2:$B$35,Справочники!$A$2:$A$35) -> Бухгалтерия | G3: Главный бухгалтер | H3: =LOOKUP(G3,Справочники!$B$2:$B$35,Справочники!$C$2:$C$35) -> 20000 | I3: высшее | J3: 34380 | K3: 25186 | L3: =DATEDIF(J3, TODAY(),"Y") -> 28 | M3: =DATEDIF(K3, TODAY(),"Y") -> 53 | N3: =LOOKUP(F3,Справочники!$F$2:$F$10,Справочники!$H$2:$H$10) -> +7(8332)64-32-01
A4: 103 | B4: Иванова | C4: Людмила | D4: Петровна | E4: жен | F4: =LOOKUP(G4,Справочники!$B$2:$B$35,Справочники!$A$2:$A$35) -> Бухгалтерия | G4: Кассир | H4: =LOOKUP(G4,Справочники!$B$2:$B$35,Справочники!$C$2:$C$35) -> 12000 | I4: среднее специальное | J4: 42962 | K4: 34762 | L4: =DATEDIF(J4, TODAY(),"Y") -> 5 | M4: =DATEDIF(K4, TODAY(),"Y") -> 27 | N4: =LOOKUP(F4,Справочники!$F$2:$F$10,Справочники!$H$2:$H$10) -> +7(8332)64-32-01
A5: 104 | B5: Лобурец | C5: Диана | D5: Борисовна | E5: жен | F5: =LOOKUP(G5,Справочники!$B$2:$B$35,Справочники!$A$2:$A$35) -> Бухгалтерия | G5: Экономист | H5: =LOOKUP(G5,Справочники!$B$2:$B$35,Справочники!$C$2:$C$35) -> 15000 | I5: высшее | J5: 41530 | K5: 25346 | L5: =DATEDIF(J5, TODAY(),"Y") -> 9 | M5: =DATEDIF(K5, TODAY(),"Y") -> 53 | N5: =LOOKUP(F5,Справочники!$F$2:$F$10,Справочники!$H$2:$H$10) -> +7(8332)64-32-01
A6: 105 | B6: Алеев | C6: Леонид | D6: Иванович | E6: муж | F6: =LOOKUP(G6,Справочники!$B$2:$B$35,Справочники!$A$2:$A$35) -> Бухгалтерия | G6: Зам. гл. бухгалтера | H6: =LOOKUP(G6,Справочники!$B$2:$B$35,Справочники!$C$2:$C$35) -> 17000 | I6: высшее | J6: 41165 | K6: 31196 | L6: =DATEDIF(J6, TODAY(),"Y") -> 10 | M6: =DATEDIF(K6, TODAY(),"Y") -> 37 | N6: =LOOKUP(F6,Справочники!$F$2:$F$10,Справочники!$H$2:$H$10) -> +7(8332)64-32-01
A7: 106 | B7: Левитин | C7: Евгений | D7: Валерьянович | E7: муж | F7: =LOOKUP(G7,Справочники!$B$2:$B$35,Справочники!$A$2:$A$35) -> Бухгалтерия | G7: Бухгалтер | H7: =LOOKUP(G7,Справочники!$B$2:$B$35,Справочники!$C$2:$C$35) -> 12000 | I7: неполное высшее | J7: 42626 | K7: 31062 | L7: =DATEDIF(J7, TODAY(),"Y") -> 6 | M7: =DATEDIF(K7, TODAY(),"Y") -> 37 | N7: =LOOKUP(F7,Справочники!$F$2:$F$10,Справочники!$H$2:$H$10) -> +7(8332)64-32-01
A8: 107 | B8: Богуславская | C8: Дарья | D8: Вячеславовна | E8: жен | F8: =LOOKUP(G8,Справочники!$B$2:$B$35,Справочники!$A$2:$A$35) -> Управление | G8: Референт | H8: =LOOKUP(G8,Справочники!$B$2:$B$35,Справочники!$C$2:$C$35) -> 15000 | I8: среднее специальное | J8: 39956 | K8: 30254 | L8: =DATEDIF(J8, TODAY(),"Y") -> 13 | M8: =DATEDIF(K8, TODAY(),"Y") -> 40 | N8: =LOOKUP(F8,Справочники!$F$2:$F$10,Справочники!$H$2:$H$10) -> +7(8332)64-32-18
A9: 108 | B9: Иванов | C9: Александр | D9: Геннадиевич | E9: муж | F9: =LOOKUP(G9,Справочники!$B$2:$B$35,Справочники!$A$2:$A$35) -> Управление | G9: Директор | H9: =LOOKUP(G9,Справочники!$B$2:$B$35,Справочники!$C$2:$C$35) -> 35000 | I9: высшее | J9: 38579 | K9: 28499 | L9: =DATEDIF(J9, TODAY(),"Y") -> 17 | M9: =DATEDIF(K9, TODAY(),"Y") -> 44 | N9: =LOOKUP(F9,Справочники!$F$2:$F$10,Справочники!$H$2:$H$10) -> +7(8332)64-32-18
A10: 109 | B10: Васильев | C10: Леонид | D10: Сергеевич | E10: муж | F10: =LOOKUP(G10,Справочники!$B$2:$B$35,Справочники!$A$2:$A$35) -> Управление | G10: Зам. директора | H10: =LOOKUP(G10,Справочники!$B$2:$B$35,Справочники!$C$2:$C$35) -> 28000 | I10: высшее | J10: 39103 | K10: 27786 | L10: =DATEDIF(J10, TODAY(),"Y") -> 15 | M10: =DATEDIF(K10, TODAY(),"Y") -> 46 | N10: =LOOKUP(F10,Справочники!$F$2:$F$10,Справочники!$H$2:$H$10) -> +7(8332)64-32-18
A11: 110 | B11: Федотова | C11: Инна | D11: Николаевна | E11: жен | F11: =LOOKUP(G11,Справочники!$B$2:$B$35,Справочники!$A$2:$A$35) -> Управление | G11: Финансовый директор | H11: =LOOKUP(G11,Справочники!$B$2:$B$35,Справочники!$C$2:$C$35) -> 30000 | I11: высшее | J11: 34436 | K11: 26821 | L11: =DATEDIF(J11, TODAY(),"Y") -> 28 | M11: =DATEDIF(K11, TODAY(),"Y") -> 49 | N11: =LOOKUP(F11,Справочники!$F$2:$F$10,Справочники!$H$2:$H$10) -> +7(8332)64-32-18
A12: 111 | B12: Прохорова | C12: Татьяна | D12: Петровна | E12: жен | F12: =LOOKUP(G12,Справочники!$B$2:$B$35,Справочники!$A$2:$A$35) -> Управление | G12: Секретарь | H12: =LOOKUP(G12,Справочники!$B$2:$B$35,Справочники!$C$2:$C$35) -> 15000 | I12: неполное высшее | J12: 42960 | K12: 33207 | L12: =DATEDIF(J12, TODAY(),"Y") -> 5 | M12: =DATEDIF(K12, TODAY(),"Y") -> 31 | N12: =LOOKUP(F12,Справочники!$F$2:$F$10,Справочники!$H$2:$H$10) -> +7(8332)64-32-18
A13: 112 | B13: Максимов | C13: Андрей | D13: Леонидович | E13: муж | F13: =LOOKUP(G13,Справочники!$B$2:$B$35,Справочники!$A$2:$A$35) -> Рекламный отдел | G13: Начальник отдела | H13: =LOOKUP(G13,Справочники!$B$2:$B$35,Справочники!$C$2:$C$35) -> 22000 | I13: высшее | J13: 40966 | K13: 31390 | L13: =DATEDIF(J13, TODAY(),"Y") -> 10 | M13: =DATEDIF(K13, TODAY(),"Y") -> 36 | N13: =LOOKUP(F13,Справочники!$F$2:$F$10,Справочники!$H$2:$H$10) -> +7(8332)64-32-01
... A65: 164 | B65: Толоконникова | C65: Майя | D65: Кириловна | E65: жен | F65: =LOOKUP(G65,Справочники!$B$2:$B$35,Справочники!$A$2:$A$35) -> Транспортный отдел | G65: Диспетчер | H65: =LOOKUP(G65,Справочники!$B$2:$B$35,Справочники!$C$2:$C$35) -> 12000 | I65: среднее | J65: 43438 | K65: 34714 | L65: =DATEDIF(J65, TODAY(),"Y") -> 3 | M65: =DATEDIF(K65, TODAY(),"Y") -> 27 | N65: =LOOKUP(F65,Справочники!$F$2:$F$10,Справочники!$H$2:$H$10) -> +7(8332)64-32-18

Sheet 2.3
A1: Табельный номер | B1: Фамилия | C1: Имя | D1: Отчество | E1: Пол | F1: Отдел | G1: Должность | H1: Оклад | I1: Образование | J1: Дата найма | K1: Дата рождения | L1: Стаж | M1: Возраст | N1: Рабочий телефон
A2: 101 | B2: Айдарпашич | C2: Амина | D2: Александровна | E2: жен | F2: =LOOKUP(G2,Справочники!$B$2:$B$35,Справочники!$A$2:$A$35) -> Бухгалтерия | G2: Бухгалтер | H2: =LOOKUP(G2,Справочники!$B$2:$B$35,Справочники!$C$2:$C$35) -> 12000 | I2: высшее | J2: 38944 | K2: 30198 | L2: =DATEDIF(J2, TODAY(),"Y") -> 16 | M2: =DATEDIF(K2, TODAY(),"Y") -> 40 | N2: =LOOKUP(F2,Справочники!$F$2:$F$10,Справочники!$H$2:$H$10) -> +7(8332)64-32-01
A3: 102 | B3: Вербицкая | C3: Елена | D3: Вадимовна | E3: жен | F3: =LOOKUP(G3,Справочники!$B$2:$B$35,Справочники!$A$2:$A$35) -> Бухгалтерия | G3: Главный бухгалтер | H3: =LOOKUP(G3,Справочники!$B$2:$B$35,Справочники!$C$2:$C$35) -> 20000 | I3: высшее | J3: 34380 | K3: 25186 | L3: =DATEDIF(J3, TODAY(),"Y") -> 28 | M3: =DATEDIF(K3, TODAY(),"Y") -> 53 | N3: =LOOKUP(F3,Справочники!$F$2:$F$10,Справочники!$H$2:$H$10) -> +7(8332)64-32-01
A4: 103 | B4: Иванова | C4: Людмила | D4: Петровна | E4: жен | F4: =LOOKUP(G4,Справочники!$B$2:$B$35,Справочники!$A$2:$A$35) -> Бухгалтерия | G4: Кассир | H4: =LOOKUP(G4,Справочники!$B$2:$B$35,Справочники!$C$2:$C$35) -> 12000 | I4: среднее специальное | J4: 42962 | K4: 34762 | L4: =DATEDIF(J4, TODAY(),"Y") -> 5 | M4: =DATEDIF(K4, TODAY(),"Y") -> 27 | N4: =LOOKUP(F4,Справочники!$F$2:$F$10,Справочники!$H$2:$H$10) -> +7(8332)64-32-01
A5: 104 | B5: Лобурец | C5: Диана | D5: Борисовна | E5: жен | F5: =LOOKUP(G5,Справочники!$B$2:$B$35,Справочники!$A$2:$A$35) -> Бухгалтерия | G5: Экономист | H5: =LOOKUP(G5,Справочники!$B$2:$B$35,Справочники!$C$2:$C$35) -> 15000 | I5: высшее | J5: 41530 | K5: 25346 | L5: =DATEDIF(J5, TODAY(),"Y") -> 9 | M5: =DATEDIF(K5, TODAY(),"Y") -> 53 | N5: =LOOKUP(F5,Справочники!$F$2:$F$10,Справочники!$H$2:$H$10) -> +7(8332)64-32-01
A6: 105 | B6: Алеев | C6: Леонид | D6: Иванович | E6: муж | F6: =LOOKUP(G6,Справочники!$B$2:$B$35,Справочники!$A$2:$A$35) -> Бухгалтерия | G6: Зам. гл. бухгалтера | H6: =LOOKUP(G6,Справочники!$B$2:$B$35,Справочники!$C$2:$C$35) -> 17000 | I6: высшее | J6: 41165 | K6: 31196 | L6: =DATEDIF(J6, TODAY(),"Y") -> 10 | M6: =DATEDIF(K6, TODAY(),"Y") -> 37 | N6: =LOOKUP(F6,Справочники!$F$2:$F$10,Справочники!$H$2:$H$10) -> +7(8332)64-32-01
A7: 106 | B7: Левитин | C7: Евгений | D7: Валерьянович | E7: муж | F7: =LOOKUP(G7,Справочники!$B$2:$B$35,Справочники!$A$2:$A$35) -> Бухгалтерия | G7: Бухгалтер | H7: =LOOKUP(G7,Справочники!$B$2:$B$35,Справочники!$C$2:$C$35) -> 12000 | I7: неполное высшее | J7: 42626 | K7: 31062 | L7: =DATEDIF(J7, TODAY(),"Y") -> 6 | M7: =DATEDIF(K7, TODAY(),"Y") -> 37 | N7: =LOOKUP(F7,Справочники!$F$2:$F$10,Справочники!$H$2:$H$10) -> +7(8332)64-32-01
A8: 107 | B8: Богуславская | C8: Дарья | D8: Вячеславовна | E8: жен | F8: =LOOKUP(G8,Справочники!$B$2:$B$35,Справочники!$A$2:$A$35) -> Управление | G8: Референт | H8: =LOOKUP(G8,Справочники!$B$2:$B$35,Справочники!$C$2:$C$35) -> 15000 | I8: среднее специальное | J8: 39956 | K8: 30254 | L8: =DATEDIF(J8, TODAY(),"Y") -> 13 | M8: =DATEDIF(K8, TODAY(),"Y") -> 40 | N8: =LOOKUP(F8,Справочники!$F$2:$F$10,Справочники!$H$2:$H$10) -> +7(8332)64-32-18
A9: 108 | B9: Иванов | C9: Александр | D9: Геннадиевич | E9: муж | F9: =LOOKUP(G9,Справочники!$B$2:$B$35,Справочники!$A$2:$A$35) -> Управление | G9: Директор | H9: =LOOKUP(G9,Справочники!$B$2:$B$35,Справочники!$C$2:$C$35) -> 35000 | I9: высшее | J9: 38579 | K9: 28499 | L9: =DATEDIF(J9, TODAY(),"Y") -> 17 | M9: =DATEDIF(K9, TODAY(),"Y") -> 44 | N9: =LOOKUP(F9,Справочники!$F$2:$F$10,Справочники!$H$2:$H$10) -> +7(8332)64-32-18
A10: 109 | B10: Васильев | C10: Леонид | D10: Сергеевич | E10: муж | F10: =LOOKUP(G10,Справочники!$B$2:$B$35,Справочники!$A$2:$A$35) -> Управление | G10: Зам. директора | H10: =LOOKUP(G10,Справочники!$B$2:$B$35,Справочники!$C$2:$C$35) -> 28000 | I10: высшее | J10: 39103 | K10: 27786 | L10: =DATEDIF(J10, TODAY(),"Y") -> 15 | M10: =DATEDIF(K10, TODAY(),"Y") -> 46 | N10: =LOOKUP(F10,Справочники!$F$2:$F$10,Справочники!$H$2:$H$10) -> +7(8332)64-32-18
A11: 110 | B11: Федотова | C11: Инна | D11: Николаевна | E11: жен | F11: =LOOKUP(G11,Справочники!$B$2:$B$35,Справочники!$A$2:$A$35) -> Управление | G11: Финансовый директор | H11: =LOOKUP(G11,Справочники!$B$2:$B$35,Справочники!$C$2:$C$35) -> 30000 | I11: высшее | J11: 34436 | K11: 26821 | L11: =DATEDIF(J11, TODAY(),"Y") -> 28 | M11: =DATEDIF(K11, TODAY(),"Y") -> 49 | N11: =LOOKUP(F11,Справочники!$F$2:$F$10,Справочники!$H$2:$H$10) -> +7(8332)64-32-18
A12: 111 | B12: Прохорова | C12: Татьяна | D12: Петровна | E12: жен | F12: =LOOKUP(G12,Справочники!$B$2:$B$35,Справочники!$A$2:$A$35) -> Управление | G12: Секретарь | H12: =LOOKUP(G12,Справочники!$B$2:$B$35,Справочники!$C$2:$C$35) -> 15000 | I12: неполное высшее | J12: 42960 | K12: 33207 | L12: =DATEDIF(J12, TODAY(),"Y") -> 5 | M12: =DATEDIF(K12, TODAY(),"Y") -> 31 | N12: =LOOKUP(F12,Справочники!$F$2:$F$10,Справочники!$H$2:$H$10) -> +7(8332)64-32-18
A13: 112 | B13: Максимов | C13: Андрей | D13: Леонидович | E13: муж | F13: =LOOKUP(G13,Справочники!$B$2:$B$35,Справочники!$A$2:$A$35) -> Рекламный отдел | G13: Начальник отдела | H13: =LOOKUP(G13,Справочники!$B$2:$B$35,Справочники!$C$2:$C$35) -> 22000 | I13: высшее | J13: 40966 | K13: 31390 | L13: =DATEDIF(J13, TODAY(),"Y") -> 10 | M13: =DATEDIF(K13, TODAY(),"Y") -> 36 | N13: =LOOKUP(F13,Справочники!$F$2:$F$10,Справочники!$H$2:$H$10) -> +7(8332)64-32-01
... A65: 164 | B65: Толоконникова | C65: Майя | D65: Кириловна | E65: жен | F65: =LOOKUP(G65,Справочники!$B$2:$B$35,Справочники!$A$2:$A$35) -> Транспортный отдел | G65: Диспетчер | H65: =LOOKUP(G65,Справочники!$B$2:$B$35,Справочники!$C$2:$C$35) -> 12000 | I65: среднее | J65: 43438 | K65: 34714 | L65: =DATEDIF(J65, TODAY(),"Y") -> 3 | M65: =DATEDIF(K65, TODAY(),"Y") -> 27 | N65: =LOOKUP(F65,Справочники!$F$2:$F$10,Справочники!$H$2:$H$10) -> +7(8332)64-32-18

Sheet 2.4
A1: Табельный номер | B1: Фамилия | C1: Имя | D1: Отчество | E1: Пол | F1: Отдел | G1: Должность | H1: Оклад | I1: Образование | J1: Дата найма | K1: Дата рождения | L1: Стаж | M1: Возраст | N1: Рабочий телефон
H2: <12 000 | I2: среднее
H3: >=15 000 | I3: среднее специальное
A6: Табельный номер | B6: Фамилия | C6: Имя | D6: Отчество | E6: Пол | F6: Отдел | G6: Должность | H6: Оклад | I6: Образование | J6: Дата найма | K6: Дата рождения | L6: Стаж | M6: Возраст | N6: Рабочий телефон
A7: 101 | B7: Айдарпашич | C7: Амина | D7: Александровна | E7: жен | F7: =LOOKUP(G7,Справочники!$B$2:$B$35,Справочники!$A$2:$A$35) -> Бухгалтерия | G7: Бухгалтер | H7: =LOOKUP(G7,Справочники!$B$2:$B$35,Справочники!$C$2:$C$35) -> 12000 | I7: высшее | J7: 38944 | K7: 30198 | L7: =DATEDIF(J7, TODAY(),"Y") -> 16 | M7: =DATEDIF(K7, TODAY(),"Y") -> 40 | N7: =LOOKUP(F7,Справочники!$F$2:$F$10,Справочники!$H$2:$H$10) -> +7(8332)64-32-01
A8: 102 | B8: Вербицкая | C8: Елена | D8: Вадимовна | E8: жен | F8: =LOOKUP(G8,Справочники!$B$2:$B$35,Справочники!$A$2:$A$35) -> Бухгалтерия | G8: Главный бухгалтер | H8: =LOOKUP(G8,Справочники!$B$2:$B$35,Справочники!$C$2:$C$35) -> 20000 | I8: высшее | J8: 34380 | K8: 25186 | L8: =DATEDIF(J8, TODAY(),"Y") -> 28 | M8: =DATEDIF(K8, TODAY(),"Y") -> 53 | N8: =LOOKUP(F8,Справочники!$F$2:$F$10,Справочники!$H$2:$H$10) -> +7(8332)64-32-01
A9: 103 | B9: Иванова | C9: Людмила | D9: Петровна | E9: жен | F9: =LOOKUP(G9,Справочники!$B$2:$B$35,Справочники!$A$2:$A$35) -> Бухгалтерия | G9: Кассир | H9: =LOOKUP(G9,Справочники!$B$2:$B$35,Справочники!$C$2:$C$35) -> 12000 | I9: среднее специальное | J9: 42962 | K9: 34762 | L9: =DATEDIF(J9, TODAY(),"Y") -> 5 | M9: =DATEDIF(K9, TODAY(),"Y") -> 27 | N9: =LOOKUP(F9,Справочники!$F$2:$F$10,Справочники!$H$2:$H$10) -> +7(8332)64-32-01
A10: 104 | B10: Лобурец | C10: Диана | D10: Борисовна | E10: жен | F10: =LOOKUP(G10,Справочники!$B$2:$B$35,Справочники!$A$2:$A$35) -> Бухгалтерия | G10: Экономист | H10: =LOOKUP(G10,Справочники!$B$2:$B$35,Справочники!$C$2:$C$35) -> 15000 | I10: высшее | J10: 41530 | K10: 25346 | L10: =DATEDIF(J10, TODAY(),"Y") -> 9 | M10: =DATEDIF(K10, TODAY(),"Y") -> 53 | N10: =LOOKUP(F10,Справочники!$F$2:$F$10,Справочники!$H$2:$H$10) -> +7(8332)64-32-01
A11: 105 | B11: Алеев | C11: Леонид | D11: Иванович | E11: муж | F11: =LOOKUP(G11,Справочники!$B$2:$B$35,Справочники!$A$2:$A$35) -> Бухгалтерия | G11: Зам. гл. бухгалтера | H11: =LOOKUP(G11,Справочники!$B$2:$B$35,Справочники!$C$2:$C$35) -> 17000 | I11: высшее | J11: 41165 | K11: 31196 | L11: =DATEDIF(J11, TODAY(),"Y") -> 10 | M11: =DATEDIF(K11, TODAY(),"Y") -> 37 | N11: =LOOKUP(F11,Справочники!$F$2:$F$10,Справочники!$H$2:$H$10) -> +7(8332)64-32-01
A12: 106 | B12: Левитин | C12: Евгений | D12: Валерьянович | E12: муж | F12: =LOOKUP(G12,Справочники!$B$2:$B$35,Справочники!$A$2:$A$35) -> Бухгалтерия | G12: Бухгалтер | H12: =LOOKUP(G12,Справочники!$B$2:$B$35,Справочники!$C$2:$C$35) -> 12000 | I12: неполное высшее | J12: 42626 | K12: 31062 | L12: =DATEDIF(J12, TODAY(),"Y") -> 6 | M12: =DATEDIF(K12, TODAY(),"Y") -> 37 | N12: =LOOKUP(F12,Справочники!$F$2:$F$10,Справочники!$H$2:$H$10) -> +7(8332)64-32-01
A13: 107 | B13: Богуславская | C13: Дарья | D13: Вячеславовна | E13: жен | F13: =LOOKUP(G13,Справочники!$B$2:$B$35,Справочники!$A$2:$A$35) -> Управление | G13: Референт | H13: =LOOKUP(G13,Справочники!$B$2:$B$35,Справочники!$C$2:$C$35) -> 15000 | I13: среднее специальное | J13: 39956 | K13: 30254 | L13: =DATEDIF(J13, TODAY(),"Y") -> 13 | M13: =DATEDIF(K13, TODAY(),"Y") -> 40 | N13: =LOOKUP(F13,Справочники!$F$2:$F$10,Справочники!$H$2:$H$10) -> +7(8332)64-32-18
A14: 108 | B14: Иванов | C14: Александр | D14: Геннадиевич | E14: муж | F14: =LOOKUP(G14,Справочники!$B$2:$B$35,Справочники!$A$2:$A$35) -> Управление | G14: Директор | H14: =LOOKUP(G14,Справочники!$B$2:$B$35,Справочники!$C$2:$C$35) -> 35000 | I14: высшее | J14: 38579 | K14: 28499 | L14: =DATEDIF(J14, TODAY(),"Y") -> 17 | M14: =DATEDIF(K14, TODAY(),"Y") -> 44 | N14: =LOOKUP(F14,Справочники!$F$2:$F$10,Справочники!$H$2:$H$10) -> +7(8332)64-32-18
A15: 109 | B15: Васильев | C15: Леонид | D15: Сергеевич | E15: муж | F15: =LOOKUP(G15,Справочники!$B$2:$B$35,Справочники!$A$2:$A$35) -> Управление | G15: Зам. директора | H15: =LOOKUP(G15,Справочники!$B$2:$B$35,Справочники!$C$2:$C$35) -> 28000 | I15: высшее | J15: 39103 | K15: 27786 | L15: =DATEDIF(J15, TODAY(),"Y") -> 15 | M15: =DATEDIF(K15, TODAY(),"Y") -> 46 | N15: =LOOKUP(F15,Справочники!$F$2:$F$10,Справочники!$H$2:$H$10) -> +7(8332)64-32-18
A16: 110 | B16: Федотова | C16: Инна | D16: Николаевна | E16: жен | F16: =LOOKUP(G16,Справочники!$B$2:$B$35,Справочники!$A$2:$A$35) -> Управление | G16: Финансовый директор | H16: =LOOKUP(G16,Справочники!$B$2:$B$35,Справочники!$C$2:$C$35) -> 30000 | I16: высшее | J16: 34436 | K16: 26821 | L16: =DATEDIF(J16, TODAY(),"Y") -> 28 | M16: =DATEDIF(K16, TODAY(),"Y") -> 49 | N16: =LOOKUP(F16,Справочники!$F$2:$F$10,Справочники!$H$2:$H$10) -> +7(8332)64-32-18
A17: 111 | B17: Прохорова | C17: Татьяна | D17: Петровна | E17: жен | F17: =LOOKUP(G17,Справочники!$B$2:$B$35,Справочники!$A$2:$A$35) -> Управление | G17: Секретарь | H17: =LOOKUP(G17,Справочники!$B$2:$B$35,Справочники!$C$2:$C$35) -> 15000 | I17: неполное высшее | J17: 42960 | K17: 33207 | L17: =DATEDIF(J17, TODAY(),"Y") -> 5 | M17: =DATEDIF(K17, TODAY(),"Y") -> 31 | N17: =LOOKUP(F17,Справочники!$F$2:$F$10,Справочники!$H$2:$H$10) -> +7(8332)64-32-18
A18: 112 | B18: Максимов | C18: Андрей | D18: Леонидович | E18: муж | F18: =LOOKUP(G18,Справочники!$B$2:$B$35,Справочники!$A$2:$A$35) -> Рекламный отдел | G18: Начальник отдела | H18: =LOOKUP(G18,Справочники!$B$2:$B$35,Справочники!$C$2:$C$35) -> 22000 | I18: высшее | J18: 40966 | K18: 31390 | L18: =DATEDIF(J18, TODAY(),"Y") -> 10 | M18: =DATEDIF(K18, TODAY(),"Y") -> 36 | N18: =LOOKUP(F18,Справочники!$F$2:$F$10,Справочники!$H$2:$H$10) -> +7(8332)64-32-01
... A70: 164 | B70: Толоконникова | C70: Майя | D70: Кириловна | E70: жен | F70: =LOOKUP(G70,Справочники!$B$2:$B$35,Справочники!$A$2:$A$35) -> Транспортный отдел | G70: Диспетчер | H70: =LOOKUP(G70,Справочники!$B$2:$B$35,Справочники!$C$2:$C$35) -> 12000 | I70: среднее | J70: 43438 | K70: 34714 | L70: =DATEDIF(J70, TODAY(),"Y") -> 3 | M70: =DATEDIF(K70, TODAY(),"Y") -> 27 | N70: =LOOKUP(F70,Справочники!$F$2:$F$10,Справочники!$H$2:$H$10) -> +7(8332)64-32-18

Sheet 2.5
